Workbook

Sheet 테스트 케이스 매트릭스
A1: 식별 | E1: 시나리오 | J1: Vitest | N1: VitePress Playground | Q1: 결과 / 조치
A2: TC_ID | B2: Layer | C2: 대상 모듈 | D2: 기능 구분 | E2: 테스트 케이스명 | F2: 시나리오 설명 | G2: 사전 조건 / Fixture | H2: 입력 데이터 | I2: 기대 결과 | J2: 실행 환경 | K2: 실행 상태 | L2: 실행 결과 메모 | M2: 코드 파일명 | N2: Playground 구현 | O2: Vue 컴포넌트명 | P2: 데모 설명 | Q2: 전체 상태 | R2: 결함 내용 | S2: 조치사항 | T2: 비고
A3: TC-C-001 | B3: Core | C3: api-proxy.js | D3: 기본 변경 추적 | E3: 존재하는 키 수정 → replace op 기록 | F3: 기존 프로퍼티에 새 값을 할당하면 changeLog에 op:'replace'가 기록된다 | G3: createProxy({ name:'Davi' }) | H3: proxy.name = 'Lee' | I3: changeLog[0] == { op:'replace', path:'/name', oldValue:'Davi', newValue:'Lee' } | J3: node | K3: 대기 | L3: OK | M3: tests/core/api-proxy.test.js | N3: N | Q3: 대기
A4: TC-C-002 | B4: Core | C4: api-proxy.js | D4: 기본 변경 추적 | E4: 없는 키 추가 → add op 기록 | F4: 존재하지 않는 프로퍼티에 값을 할당하면 op:'add'가 기록된다 | G4: createProxy({ name:'Davi' }) | H4: proxy.phone = '010' | I4: changeLog[0] == { op:'add', path:'/phone', newValue:'010' } | J4: node | K4: 대기 | L4: OK | M4: tests/core/api-proxy.test.js | N4: N | Q4: 대기
A5: TC-C-003 | B5: Core | C5: api-proxy.js | D5: 기본 변경 추적 | E5: delete 연산 → remove op 기록 | F5: delete 연산자로 프로퍼티를 삭제하면 op:'remove'가 기록된다 | G5: createProxy({ name:'Davi', age:30 }) | H5: delete proxy.age | I5: changeLog[0] == { op:'remove', path:'/age', oldValue:30 } | J5: node | K5: 대기 | L5: OK | M5: tests/core/api-proxy.test.js | N5: N | Q5: 대기
A6: TC-C-004 | B6: Core | C6: api-proxy.js | D6: 기본 변경 추적 | E6: 동일 값 재할당 → No-op | F6: 현재 값과 동일한 값을 할당하면 changeLog에 기록되지 않는다 | G6: createProxy({ name:'Davi' }) | H6: proxy.name = 'Davi' | I6: changeLog.length === 0 | J6: node | K6: 대기 | L6: OK | M6: tests/core/api-proxy.test.js | N6: N | Q6: 대기
A7: TC-C-005 | B7: Core | C7: api-proxy.js | D7: 중첩 객체 추적 | E7: 중첩 객체 수정 → 경로에 부모/자식 포함 | F7: 중첩 객체 내부 값 변경 시 path가 /부모/자식 형태로 기록된다 | G7: createProxy({ address:{ city:'Seoul' } }) | H7: proxy.address.city = 'Busan' | I7: changeLog[0].path === '/address/city' | J7: node | K7: 대기 | L7: OK | M7: tests/core/api-proxy.test.js | N7: N | Q7: 대기
A8: TC-C-006 | B8: Core | C8: api-proxy.js | D8: 중첩 객체 추적 | E8: 동일 중첩 객체 재접근 → WeakMap 캐싱 | F8: 같은 중첩 객체에 두 번 접근해도 Proxy를 새로 생성하지 않는다 | G8: createProxy({ address:{ city:'Seoul' } }) | H8: const a1 = proxy.address; const a2 = proxy.address; | I8: a1 === a2 (동일 참조) | J8: node | K8: 대기 | L8: OK | M8: tests/core/api-proxy.test.js | N8: N | Q8: 대기
A9: TC-C-007 | B9: Core | C9: api-proxy.js | D9: 배열 변이 추적 | E9: push → add op (마지막 인덱스) | F9: push() 호출 시 새 인덱스에 add op가 기록된다 | G9: createProxy({ items:['A','B'] }) | H9: proxy.items.push('C') | I9: changeLog에 op:'add', path:'/items/2', newValue:'C' 포함 | J9: node | K9: 대기 | L9: OK | M9: tests/core/api-proxy.test.js | N9: N | Q9: 대기
A10: TC-C-008 | B10: Core | C10: api-proxy.js | D10: 배열 변이 추적 | E10: splice → 정확한 인덱스 REMOVE + ADD | F10: splice(1,1,'X') 호출 시 index 1에 remove/add가 순서대로 기록된다 | G10: createProxy({ items:['A','B','C'] }) | H10: proxy.items.splice(1, 1, 'X') | I10: REMOVE /items/1 oldValue:'B', ADD /items/1 newValue:'X' 순서로 기록 | J10: node | K10: 대기 | L10: OK | M10: tests/core/api-proxy.test.js | N10: N | Q10: 대기
A11: TC-C-009 | B11: Core | C11: api-proxy.js | D11: 배열 변이 추적 | E11: sort → 배열 전체 단일 replace op | F11: sort() 호출 시 배열 전체가 단일 replace op로 기록된다 | G11: createProxy({ items:['C','A','B'] }) | H11: proxy.items.sort() | I11: changeLog에 op:'replace', path:'/items' 인 항목 1개만 존재 | J11: node | K11: 대기 | L11: OK | M11: tests/core/api-proxy.test.js | N11: N | Q11: 대기
A12: TC-C-010 | B12: Core | C12: api-proxy.js | D12: dirtyFields (1-A) | E12: 최상위 키 변경 → dirtyFields 등록 | F12: 최상위 키를 수정하면 dirtyFields에 해당 키가 포함된다 | G12: createProxy({ name:'Davi', age:30 }) | H12: proxy.name = 'Lee' | I12: getDirtyFields().has('name') === true | J12: node | K12: 대기 | L12: OK | M12: tests/core/api-proxy.test.js | N12: Y | O12: DirtyFieldsDemo | P12: name 변경 → dirtyFields 실시간 시각화 | Q12: 대기
A13: TC-C-011 | B13: Core | C13: api-proxy.js | D13: dirtyFields (1-A) | E13: 중첩 키 변경 → 최상위 키만 등록 | F13: /address/city 변경 시 dirtyFields에는 'address'만 추가된다 | G13: createProxy({ address:{ city:'Seoul' } }) | H13: proxy.address.city = 'Busan' | I13: getDirtyFields() == Set { 'address' } | J13: node | K13: 대기 | L13: OK | M13: tests/core/api-proxy.test.js | N13: Y | O13: DirtyFieldsDemo | P13: 중첩 경로 분해 원리 시각화 | Q13: 대기
A14: TC-C-012 | B14: Core | C14: api-proxy.js | D14: dirtyFields (1-A) | E14: 동일 키 반복 변경 → size 유지 | F14: 같은 키를 10번 바꿔도 dirtyFields.size는 1이다 | G14: createProxy({ name:'A' }) | H14: proxy.name = 'B'; proxy.name = 'C'; ... (10회) | I14: getDirtyFields().size === 1 | J14: node | K14: 대기 | L14: OK | M14: tests/core/api-proxy.test.js | N14: N | Q14: 대기
A15: TC-C-013 | B15: Core | C15: api-proxy.js | D15: 복원 메서드 (1-D) | E15: restoreTarget → domainObject 복원 | F15: restoreTarget(snapshot) 호출 후 domainObject가 스냅샷 값으로 복원된다 | G15: proxy.name = 'Lee' 변경 후 | H15: restoreTarget({ name:'Davi' }) | I15: getTarget().name === 'Davi' | J15: node | K15: 대기 | L15: OK | M15: tests/core/api-proxy.test.js | N15: Y | O15: RollbackDemo | P15: 복원 전/후 상태 비교 시각화 | Q15: 대기
A16: TC-C-014 | B16: Core | C16: api-proxy.js | D16: 복원 메서드 (1-D) | E16: restoreTarget → changeLog에 기록 안 됨 | F16: restoreTarget은 Proxy를 우회하므로 복원 자체가 changeLog에 기록되지 않는다 | G16: 변경 후 changeLog가 있는 상태 | H16: restoreTarget(snapshot) | I16: 복원 후 getChangeLog().length === 변경 시 log 수 (증가 없음) | J16: node | K16: 대기 | L16: OK | M16: tests/core/api-proxy.test.js | N16: N | Q16: 대기
A17: TC-C-015 | B17: Core | C17: api-proxy.js | D17: 복원 메서드 (1-D) | E17: Array 루트 객체 복원 | F17: domainObject가 배열일 때 restoreTarget은 splice/push로 복원한다 | G17: createProxy(['A','B','C']) | H17: proxy[0]='X'; restoreTarget(['A','B','C']) | I17: getTarget() deep-equals ['A','B','C'] | J17: node | K17: 대기 | L17: OK | M17: tests/core/api-proxy.test.js | N17: N | Q17: 대기
A18: TC-V-001 | B18: Domain | C18: DomainVO.js | D18: toSkeleton() | E18: static fields default 값으로 골격 생성 | F18: 선언된 각 필드의 default 값으로 객체가 초기화된다 | G18: class UserVO { static fields = { name:{default:''}, age:{default:0} } } | H18: new UserVO().toSkeleton() | I18: { name:'', age:0 } | J18: node | K18: 대기 | L18: OK | M18: tests/domain/DomainVO.test.js | N18: N | Q18: 대기
A19: TC-V-002 | B19: Domain | C19: DomainVO.js | D19: toSkeleton() | E19: 객체 default → deep copy | F19: default가 객체인 필드는 인스턴스마다 독립 참조를 갖는다 | G19: class AddrVO { static fields = { address:{ default:{ city:'' } } } } | H19: const a=new AddrVO().toSkeleton(); const b=new AddrVO().toSkeleton(); | I19: a.address !== b.address (참조 다름) | J19: node | K19: 대기 | L19: OK | M19: tests/domain/DomainVO.test.js | N19: N | Q19: 대기
A20: TC-V-003 | B20: Domain | C20: DomainVO.js | D20: checkSchema() | E20: missingKey → valid:false | F20: 응답 데이터에 VO 스키마 키가 누락되면 valid:false를 반환한다 | G20: class UserVO { static fields = { name:{default:''}, role:{default:''} } } | H20: new UserVO().checkSchema({ name:'Davi' }) | I20: { valid:false, missingKeys:['role'], extraKeys:[] } | J20: node | K20: 대기 | L20: OK | M20: tests/domain/DomainVO.test.js | N20: N | Q20: 대기
A21: TC-V-004 | B21: Domain | C21: DomainVO.js | D21: checkSchema() | E21: extraKey → valid:true (경고만) | F21: 응답에 VO에 없는 키가 있어도 valid:true이다 | G21: class UserVO { static fields = { name:{default:''} } } | H21: new UserVO().checkSchema({ name:'Davi', extra:'unknown' }) | I21: { valid:true, missingKeys:[], extraKeys:['extra'] } | J21: node | K21: 대기 | L21: OK | M21: tests/domain/DomainVO.test.js | N21: N | Q21: 대기
A22: TC-DS-001 | B22: Domain | C22: DomainState.js | D22: save() 분기 (1-A/1-B) | E22: isNew===true → POST | F22: isNew가 true인 상태에서 save() 호출 시 POST 메서드로 전송된다 | G22: DomainState.fromVO(new UserVO(), mockHandler) | H22: await state.save('/api/users') | I22: mockHandler._fetch 호출 시 method === 'POST' | J22: node | K22: 대기 | L22: OK | M22: tests/domain/DomainState.test.js | N22: Y | O22: HttpMethodDemo | P22: isNew 상태에 따른 HTTP 메서드 자동 분기 시각화 | Q22: 대기
A23: TC-DS-002 | B23: Domain | C23: DomainState.js | D23: save() 분기 (1-A/1-B) | E23: POST 성공 → isNew false 전환 | F23: POST 성공 후 다음 save()는 PUT/PATCH로 분기된다 | G23: isNew:true인 DomainState, POST mock 성공 응답 | H23: await state.save(); // 첫 번째 | I23: state._isNew === false | J23: node | K23: 대기 | L23: OK | M23: tests/domain/DomainState.test.js | N23: N | Q23: 대기
A24: TC-DS-003 | B24: Domain | C24: DomainState.js | D24: save() 분기 (1-A/1-B) | E24: dirtyFields.size===0 → PUT | F24: 변경 없이 save() 호출 시 PUT으로 전송된다 | G24: fromJSON으로 생성 후 data 수정 없이 | H24: await state.save('/api/users/1') | I24: method === 'PUT' | J24: node | K24: 대기 | L24: OK | M24: tests/domain/DomainState.test.js | N24: Y | O24: HttpMethodDemo | P24: 변경 없음 → PUT 분기 | Q24: 대기
A25: TC-DS-004 | B25: Domain | C25: DomainState.js | D25: save() 분기 (1-A/1-B) | E25: dirtyRatio >= 0.7 → PUT | F25: 전체 필드 중 70% 이상이 변경되면 PUT으로 전송된다 | G25: 5개 필드 중 4개(80%) 변경 | H25: 4개 필드 수정 후 await state.save() | I25: method === 'PUT' | J25: node | K25: 대기 | L25: OK | M25: tests/domain/DomainState.test.js | N25: Y | O25: HttpMethodDemo | P25: dirty ratio 슬라이더로 분기 변화 시각화 | Q25: 대기
A26: TC-DS-005 | B26: Domain | C26: DomainState.js | D26: save() 분기 (1-A/1-B) | E26: dirtyRatio < 0.7 → PATCH + RFC 6902 payload | F26: 변경 필드 비율이 70% 미만이면 PATCH로 전송하고 payload가 RFC 6902 형식이다 | G26: 5개 필드 중 1개(20%) 변경 | H26: 1개 필드 수정 후 await state.save() | I26: method === 'PATCH', body == JSON.parse된 배열, 항목에 op/path/value 포함 | J26: node | K26: 대기 | L26: OK | M26: tests/domain/DomainState.test.js | N26: Y | O26: HttpMethodDemo | P26: PATCH payload 내용 실시간 표시 | Q26: 대기
A27: TC-DS-006 | B27: Domain | C27: DomainState.js | D27: Optimistic Rollback (1-D) | E27: HTTP 4xx → save() 진입 시점 상태가 오염되지 않음 | F27: save() 중 중간에 내부 상태가 오염되지 않는다 | G27: mockHandler를 409 응답으로 설정, proxy.name='Lee' 변경 후 | H27: await state.save() → 409 throw 예상 | I27: mutation 값이 그대로 유지, save() 진입 시점 이력이 intact, 재시도 가능 여부: rollback 후 `_fetch` 메서드 호출이 올바름 | J27: node | K27: 대기 | L27: OK | M27: tests/domain/DomainState.test.js | N27: Y | O27: RollbackDemo | P27: 저장 실패 → 자동 롤백 애니메이션 | Q27: 대기
A28: TC-DS-007 | B28: Domain | C28: DomainState.js | D28: Optimistic Rollback (1-D) | E28: HTTP 오류 → changeLog 복원 | F28: save() 실패 시 changeLog가 save() 진입 이전 항목으로 복원된다 | G28: 409 mock, 변경 후 changeLog에 항목 있음 | H28: await state.save() catch | I28: 복원 후 getChangeLog()가 save() 이전과 동일 | J28: node | K28: 대기 | L28: OK | M28: tests/domain/DomainState.test.js | N28: N | Q28: 대기
A29: TC-DS-008 | B29: Domain | C29: DomainState.js | D29: Optimistic Rollback (1-D) | E29: HTTP 오류 → 에러 re-throw | F29: 롤백 후 에러가 호출자에게 다시 전파된다 | G29: 409 mock | H29: try { await state.save() } catch(e) { ... } | I29: catch 블록이 실행되고 e.status === 409 | J29: node | K29: 대기 | L29: OK | M29: tests/domain/DomainState.test.js | N29: N | Q29: 대기
A30: TC-DS-009 | B30: Domain | C30: DomainState.js | D30: Optimistic Rollback (1-D) | E30: 롤백 후 재시도 → 올바른 메서드 | F30: 롤백 후 재시도 시 복원된 상태 기반으로 올바른 HTTP 메서드가 선택된다 | G30: 409 후 롤백된 상태 | H30: 롤백 후 다시 await state.save() | I30: 재시도 시 PATCH (변경분 1개 있는 경우) | J30: node | K30: 대기 | L30: OK | M30: tests/domain/DomainState.test.js | N30: Y | O30: RollbackDemo | P30: 재시도 시나리오 인터랙티브 데모 | Q30: 대기
A31: TC-DS-010 | B31: Domain | C31: DomainState.js | D31: Batching (1-C) | E31: 동기 블록 다중 변경 → _broadcast 1회 | F31: 동기 블록 안에서 필드 3개를 바꿔도 _broadcast는 microtask 후 단 1번 실행된다 | G31: debug:true 인 DomainState, _broadcast를 vi.fn()으로 spy | H31: proxy.name='A'; proxy.email='B'; proxy.role='C' | I31: await (microtask flush), _broadcast 호출 횟수 === 1 | J31: node | K31: 대기 | L31: OK | M31: tests/domain/DomainState.test.js | N31: Y | O31: BatchingDemo | P31: 변경 카운터 vs 브로드캐스트 카운터 비교 시각화 | Q31: 대기
A32: TC-DS-011 | B32: Domain | C32: DomainState.js | D32: Batching (1-C) | E32: await 경계 → 각 블록 별도 flush | F32: await 경계를 넘으면 각 동기 블록이 독립적으로 flush된다 | G32: debug:true 인 DomainState, spy 설정 | H32: proxy.a='1'; await delay(); proxy.b='2'; | I32: _broadcast 총 2회 호출 | J32: node | K32: 대기 | L32: OK | M32: tests/domain/DomainState.test.js | N32: N | Q32: 대기
A33: TC-N-001 | B33: Network | C33: api-handler.js | D33: _fetch() | E33: response.ok=true → 응답 텍스트 반환 | F33: 성공 응답 시 텍스트를 반환한다 | G33: global.fetch를 200 응답으로 mock | H33: await handler._fetch('/api/test', { method:'GET' }) | I33: 반환값 === 응답 본문 텍스트 | J33: node | K33: 대기 | L33: OK | M33: tests/network/api-handler.test.js | N33: N | Q33: 대기
A34: TC-N-002 | B34: Network | C34: api-handler.js | D34: _fetch() | E34: response.ok=false → HttpError throw | F34: 4xx/5xx 응답 시 { status, statusText, body } 구조의 에러를 throw한다 | G34: global.fetch를 409 응답으로 mock | H34: await handler._fetch('/api/test', { method:'PUT' }) | I34: throw된 에러: e.status===409, e.statusText, e.body 존재 | J34: node | K34: 대기 | L34: OK | M34: tests/network/api-handler.test.js | N34: N | Q34: 대기
A35: TC-N-003 | B35: Network | C35: api-handler.js | D35: _fetch() | E35: 204 No Content → null 반환 | F35: 빈 응답 본문일 때 null을 반환한다 | G35: global.fetch를 204 빈 응답으로 mock | H35: await handler._fetch('/api/test', { method:'DELETE' }) | I35: 반환값 === null | J35: node | K35: 대기 | L35: OK | M35: tests/network/api-handler.test.js | N35: N | Q35: 대기
A36: TC-N-004 | B36: Network | C36: api-handler.js | D36: get() | E36: GET 성공 → DomainState(isNew:false) 반환 | F36: GET 응답 JSON으로 DomainState가 생성되고 isNew가 false이다 | G36: fetch를 JSON 응답으로 mock | H36: const ds = await handler.get('/api/users/1') | I36: ds instanceof DomainState && ds._isNew === false | J36: node | K36: 대기 | L36: OK | M36: tests/network/api-handler.test.js | N36: N | Q36: 대기
A37: TC-P-001 | B37: Domain | C37: DomainPipeline.js | D37: after() | E37: 존재하지 않는 key → 즉시 Error | F37: resourceMap에 없는 key를 after()에 전달하면 즉시 Error를 throw한다 | G37: new DomainPipeline({ user: Promise.resolve(ds) }) | H37: .after('nonExistent', handler) | I37: Error 즉시 throw | J37: node | K37: 대기 | L37: OK | M37: tests/domain/DomainPipeline.test.js | N37: N | Q37: 대기
A38: TC-P-002 | B38: Domain | C38: DomainPipeline.js | D38: run() strict:false | E38: fetch 실패 → _errors 기록, 나머지 계속 | F38: 일부 fetch 실패 시 _errors에 기록되고 나머지 리소스는 정상 반환된다 | G38: user: 성공 mock, role: 실패 mock | H38: await pipeline.run() | I38: result.user 존재, result._errors[0].key === 'role' | J38: node | K38: 대기 | L38: OK | M38: tests/domain/DomainPipeline.test.js | N38: N | Q38: 대기
A39: TC-P-003 | B39: Domain | C39: DomainPipeline.js | D39: run() strict:true | E39: fetch 실패 → 즉시 reject | F39: strict:true 일 때 fetch 실패 시 Promise가 즉시 reject된다 | G39: role: 실패 mock, strict:true | H39: await pipeline.run() | I39: reject, catch 블록 실행 | J39: node | K39: 대기 | L39: OK | M39: tests/domain/DomainPipeline.test.js | N39: N | Q39: 대기
A40: TC-P-004 | B40: Domain | C40: DomainPipeline.js | D40: run() 핸들러 순서 | E40: after() 등록 순서 === 실행 순서 | F40: after()로 등록된 핸들러는 등록된 순서대로 순차 실행된다 | G40: 두 리소스 성공 mock | H40: .after('a', h1).after('b', h2).run() | I40: h1 완료 후 h2 실행 (callOrder 검증) | J40: node | K40: 대기 | L40: OK | M40: tests/domain/DomainPipeline.test.js | N40: N | Q40: 대기
...

Sheet 진행 현황
A1: DSM 테스트 진행 현황
A3: Layer | B3: 전체 | C3: 대기 | D3: 통과 | E3: 실패 | F3: 통과율
A4: Core | B4: =COUNTIF('테스트 케이스 매트릭스'!B:B,A4) -> 15 | C4: =COUNTIFS('테스트 케이스 매트릭스'!B:B,A4,'테스트 케이스 매트릭스'!Q:Q,"대기") -> 15 | D4: =COUNTIFS('테스트 케이스 매트릭스'!B:B,A4,'테스트 케이스 매트릭스'!Q:Q,"통과") -> 0 | E4: =COUNTIFS('테스트 케이스 매트릭스'!B:B,A4,'테스트 케이스 매트릭스'!Q:Q,"실패") -> 0 | F4: =IFERROR(D4/B4,0) -> 0
A5: Domain | B5: =COUNTIF('테스트 케이스 매트릭스'!B:B,A5) -> 19 | C5: =COUNTIFS('테스트 케이스 매트릭스'!B:B,A5,'테스트 케이스 매트릭스'!Q:Q,"대기") -> 19 | D5: =COUNTIFS('테스트 케이스 매트릭스'!B:B,A5,'테스트 케이스 매트릭스'!Q:Q,"통과") -> 0 | E5: =COUNTIFS('테스트 케이스 매트릭스'!B:B,A5,'테스트 케이스 매트릭스'!Q:Q,"실패") -> 0 | F5: =IFERROR(D5/B5,0) -> 0
A6: Network | B6: =COUNTIF('테스트 케이스 매트릭스'!B:B,A6) -> 4 | C6: =COUNTIFS('테스트 케이스 매트릭스'!B:B,A6,'테스트 케이스 매트릭스'!Q:Q,"대기") -> 4 | D6: =COUNTIFS('테스트 케이스 매트릭스'!B:B,A6,'테스트 케이스 매트릭스'!Q:Q,"통과") -> 0 | E6: =COUNTIFS('테스트 케이스 매트릭스'!B:B,A6,'테스트 케이스 매트릭스'!Q:Q,"실패") -> 0 | F6: =IFERROR(D6/B6,0) -> 0
A7: Plugin | B7: =COUNTIF('테스트 케이스 매트릭스'!B:B,A7) -> 7 | C7: =COUNTIFS('테스트 케이스 매트릭스'!B:B,A7,'테스트 케이스 매트릭스'!Q:Q,"대기") -> 7 | D7: =COUNTIFS('테스트 케이스 매트릭스'!B:B,A7,'테스트 케이스 매트릭스'!Q:Q,"통과") -> 0 | E7: =COUNTIFS('테스트 케이스 매트릭스'!B:B,A7,'테스트 케이스 매트릭스'!Q:Q,"실패") -> 0 | F7: =IFERROR(D7/B7,0) -> 0
A8: 합계 | B8: =SUM(B4:B7) -> 45 | C8: =SUM(C4:C7) -> 45 | D8: =SUM(D4:D7) -> 0 | E8: =SUM(E4:E7) -> 0 | F8: =IFERROR(D8/B8,0) -> 0
A10: Playground 대상 케이스
A11: Playground 구현 예정 | B11: =COUNTIF('테스트 케이스 매트릭스'!N:N,"Y") -> 14

Sheet 컬럼 가이드
A1: 컬럼 작성 가이드
A2: 컬럼명 | B2: 그룹 | C2: 용도 설명 | D2: 작성 예시 / 허용값
A3: TC_ID | B3: 식별 | C3: 테스트 케이스 고유 식별자. Layer 접두사 + 순번 | D3: TC-C-001, TC-DS-006
A4: Layer | B4: 식별 | C4: 코드 레이어 분류 | D4: Core / Domain / Network / Plugin
A5: 대상 모듈 | B5: 식별 | C5: 테스트 대상 파일명 | D5: api-proxy.js, DomainState.js
A6: 기능 구분 | B6: 식별 | C6: 같은 파일 내 기능 범주 묶음. 필터링 기준 | D6: dirtyFields (1-A), 배열 변이 추적
A7: 테스트 케이스명 | B7: 시나리오 | C7: it() 설명 텍스트와 1:1 대응되는 간결한 이름 | D7: 동일 값 재할당 → No-op
A8: 시나리오 설명 | B8: 시나리오 | C8: 무엇을 검증하는지 한 문장으로 명확히 서술 | D8: 기존 프로퍼티에 동일한 값 할당 시 changeLog에 기록되지 않는다
A9: 사전 조건 / Fixture | B9: 시나리오 | C9: beforeEach에 해당하는 초기 상태 또는 Fixture | D9: createProxy({ name:'Davi', age:30 })
A10: 입력 데이터 | B10: 시나리오 | C10: 테스트 본체에서 실행하는 코드 또는 값 | D10: proxy.name = 'Davi' (동일값)
A11: 기대 결과 | B11: 시나리오 | C11: expect().toBe()에 해당하는 검증 내용 | D11: changeLog.length === 0
A12: 실행 환경 | B12: Vitest | C12: node: 브라우저 API 불필요 / jsdom: DOM 접근 필요 | D12: node / jsdom
A13: 실행 상태 | B13: Vitest | C13: vitest run 실행 후 결과 기록. 드롭다운 선택 | D13: 대기 / 통과 / 실패 / 보류
... A22: 비고 | B22: 결과/조치 | C22: 관련 GitHub 이슈, PR, 참고 링크 등 자유 기재 | D22: #42 참조, RFC 6902 §4.1
